Starting Container
[2025-10-14 13:32:29 +0000] [1] [INFO] Starting gunicorn 23.0.0
[2025-10-14 13:32:29 +0000] [1] [INFO] Listening at: http://0.0.0.0:8080 (1)
[2025-10-14 13:32:29 +0000] [1] [INFO] Using worker: sync
[2025-10-14 13:32:29 +0000] [2] [INFO] Booting worker with pid: 2
2025-10-14 13:32:47,194 - main - ERROR - Exception on /appointments/meus-agendamentos [GET]
Traceback (most recent call last):
  File "/app/.venv/lib/python3.13/site-packages/flask/app.py", line 1511, in wsgi_app
    response = self.full_dispatch_request()
  File "/app/.venv/lib/python3.13/site-packages/flask/app.py", line 919, in full_dispatch_request
    rv = self.handle_user_exception(e)
  File "/app/.venv/lib/python3.13/site-packages/flask_restful/__init__.py", line 298, in error_router
    return original_handler(e)
  File "/app/.venv/lib/python3.13/site-packages/flask_cors/extension.py", line 176, in wrapped_function
    return cors_after_request(app.make_response(f(*args, **kwargs)))
                                                ~^^^^^^^^^^^^^^^^^
  File "/app/.venv/lib/python3.13/site-packages/flask/app.py", line 917, in full_dispatch_request
    rv = self.dispatch_request()
  File "/app/.venv/lib/python3.13/site-packages/flask/app.py", line 902, in dispatch_request
    return self.ensure_sync(self.view_functions[rule.endpoint])(**view_args)  # type: ignore[no-any-return]
           ~~~~~~~~~~~~~~~~~~~~~~~~~~~~~~~~~~~~~~~~~~~~~~~~~~~~^^^^^^^^^^^^^
  File "/app/.venv/lib/python3.13/site-packages/flask_login/utils.py", line 290, in decorated_view
    return current_app.ensure_sync(func)(*args, **kwargs)
           ~~~~~~~~~~~~~~~~~~~~~~~~~~~~~^^^^^^^^^^^^^^^^^
  File "/app/app/blueprints/appointments.py", line 204, in meus_agendamentos
    return render_template('appointments/meus_agendamentos.html',
                         agendamentos=agendamentos,
                         agora=agora)
  File "/app/.venv/lib/python3.13/site-packages/flask/templating.py", line 150, in render_template
    return _render(app, template, context)
  File "/app/.venv/lib/python3.13/site-packages/flask/templating.py", line 131, in _render
    rv = template.render(context)
  File "/app/.venv/lib/python3.13/site-packages/jinja2/environment.py", line 1295, in render
    self.environment.handle_exception()
    ~~~~~~~~~~~~~~~~~~~~~~~~~~~~~~~~~^^
  File "/app/.venv/lib/python3.13/site-packages/jinja2/environment.py", line 942, in handle_exception
    raise rewrite_traceback_stack(source=source)
  File "/app/app/templates/appointments/meus_agendamentos.html", line 1, in top-level template code
    {% extends "base.html" %}
  File "/app/app/templates/base.html", line 298, in top-level template code
    {% block content %}{% endblock %}
    ^^^^^^^^^^^^^^^^^
  File "/app/app/templates/appointments/meus_agendamentos.html", line 141, in block 'content'
    <a href="{{ url_for('appointments.detalhes', agendamento_id=agendamento.id) }}"
    
  File "/app/.venv/lib/python3.13/site-packages/flask/app.py", line 1121, in url_for
    return self.handle_url_build_error(error, endpoint, values)
           ~~~~~~~~~~~~~~~~~~~~~~~~~~~^^^^^^^^^^^^^^^^^^^^^^^^^
  File "/app/.venv/lib/python3.13/site-packages/flask/app.py", line 1110, in url_for
    rv = url_adapter.build(  # type: ignore[union-attr]
        endpoint,
    ...<3 lines>...
        force_external=_external,
    )
  File "/app/.venv/lib/python3.13/site-packages/werkzeug/routing/map.py", line 924, in build
    raise BuildError(endpoint, values, method, self)
werkzeug.routing.exceptions.BuildError: Could not build url for endpoint 'appointments.detalhes' with values ['agendamento_id']. Did you mean 'appointments.sucesso' instead?